[2025-06-06T09:47:49.807+0000] {local_task_job_runner.py:120} INFO - ::group::Pre task execution logs
[2025-06-06T09:47:49.822+0000] {taskinstance.py:2073} INFO - Dependencies all met for dep_context=non-requeueable deps ti=<TaskInstance: pokemon_partitioned_to_kafka.fetch_pokemon_and_send_partitioned_to_kafka scheduled__2025-06-06T09:46:00+00:00 [queued]>
[2025-06-06T09:47:49.827+0000] {taskinstance.py:2073} INFO - Dependencies all met for dep_context=requeueable deps ti=<TaskInstance: pokemon_partitioned_to_kafka.fetch_pokemon_and_send_partitioned_to_kafka scheduled__2025-06-06T09:46:00+00:00 [queued]>
[2025-06-06T09:47:49.827+0000] {taskinstance.py:2303} INFO - Starting attempt 1 of 1
[2025-06-06T09:47:49.834+0000] {taskinstance.py:2327} INFO - Executing <Task(PythonOperator): fetch_pokemon_and_send_partitioned_to_kafka> on 2025-06-06 09:46:00+00:00
[2025-06-06T09:47:49.838+0000] {logging_mixin.py:188} WARNING - /home/***/.local/lib/python3.12/site-packages/***/task/task_runner/standard_task_runner.py:61 DeprecationWarning: This process (pid=1877) is multi-threaded, use of fork() may lead to deadlocks in the child.
[2025-06-06T09:47:49.838+0000] {standard_task_runner.py:90} INFO - Running: ['***', 'tasks', 'run', 'pokemon_partitioned_to_kafka', 'fetch_pokemon_and_send_partitioned_to_kafka', 'scheduled__2025-06-06T09:46:00+00:00', '--job-id', '95', '--raw', '--subdir', 'DAGS_FOLDER/pkapi_to_kafka_dag.py', '--cfg-path', '/tmp/tmp2nox8x2g']
[2025-06-06T09:47:49.840+0000] {standard_task_runner.py:91} INFO - Job 95: Subtask fetch_pokemon_and_send_partitioned_to_kafka
[2025-06-06T09:47:49.839+0000] {standard_task_runner.py:63} INFO - Started process 1889 to run task
[2025-06-06T09:47:49.850+0000] {logging_mixin.py:188} WARNING - /home/***/.local/lib/python3.12/site-packages/***/settings.py:195 DeprecationWarning: The sql_alchemy_conn option in [core] has been moved to the sql_alchemy_conn option in [database] - the old setting has been used, but please update your config.
[2025-06-06T09:47:49.869+0000] {task_command.py:426} INFO - Running <TaskInstance: pokemon_partitioned_to_kafka.fetch_pokemon_and_send_partitioned_to_kafka scheduled__2025-06-06T09:46:00+00:00 [running]> on host 856ef77f0083
[2025-06-06T09:47:49.917+0000] {taskinstance.py:2644} INFO - Exporting env vars: AIRFLOW_CTX_DAG_OWNER='***' AIRFLOW_CTX_DAG_ID='pokemon_partitioned_to_kafka' AIRFLOW_CTX_TASK_ID='fetch_pokemon_and_send_partitioned_to_kafka' AIRFLOW_CTX_EXECUTION_DATE='2025-06-06T09:46:00+00:00' AIRFLOW_CTX_TRY_NUMBER='1' AIRFLOW_CTX_DAG_RUN_ID='scheduled__2025-06-06T09:46:00+00:00'
[2025-06-06T09:47:49.918+0000] {taskinstance.py:430} INFO - ::endgroup::
[2025-06-06T09:47:49.935+0000] {logging_mixin.py:188} INFO - Error fetching Pokémon ID 1: HTTPSConnectionPool(host='pokeapi.co', port=443): Max retries exceeded with url: /api/v2/pokemon/1/ (Caused by NewConnectionError('<urllib3.connection.HTTPSConnection object at 0xffff7a941040>: Failed to establish a new connection: [Errno -2] Name or service not known'))
[2025-06-06T09:47:49.939+0000] {logging_mixin.py:188} INFO - Error fetching Pokémon ID 2: HTTPSConnectionPool(host='pokeapi.co', port=443): Max retries exceeded with url: /api/v2/pokemon/2/ (Caused by NewConnectionError('<urllib3.connection.HTTPSConnection object at 0xffff855bf350>: Failed to establish a new connection: [Errno -2] Name or service not known'))
[2025-06-06T09:47:49.943+0000] {logging_mixin.py:188} INFO - Error fetching Pokémon ID 3: HTTPSConnectionPool(host='pokeapi.co', port=443): Max retries exceeded with url: /api/v2/pokemon/3/ (Caused by NewConnectionError('<urllib3.connection.HTTPSConnection object at 0xffff855beed0>: Failed to establish a new connection: [Errno -2] Name or service not known'))
[2025-06-06T09:47:49.948+0000] {logging_mixin.py:188} INFO - Error fetching Pokémon ID 4: HTTPSConnectionPool(host='pokeapi.co', port=443): Max retries exceeded with url: /api/v2/pokemon/4/ (Caused by NewConnectionError('<urllib3.connection.HTTPSConnection object at 0xffff855bf440>: Failed to establish a new connection: [Errno -2] Name or service not known'))
[2025-06-06T09:47:49.954+0000] {logging_mixin.py:188} INFO - Error fetching Pokémon ID 5: HTTPSConnectionPool(host='pokeapi.co', port=443): Max retries exceeded with url: /api/v2/pokemon/5/ (Caused by NewConnectionError('<urllib3.connection.HTTPSConnection object at 0xffff855bfb00>: Failed to establish a new connection: [Errno -2] Name or service not known'))
[2025-06-06T09:47:49.958+0000] {logging_mixin.py:188} INFO - Error fetching Pokémon ID 6: HTTPSConnectionPool(host='pokeapi.co', port=443): Max retries exceeded with url: /api/v2/pokemon/6/ (Caused by NewConnectionError('<urllib3.connection.HTTPSConnection object at 0xffff855bf050>: Failed to establish a new connection: [Errno -2] Name or service not known'))
[2025-06-06T09:47:49.962+0000] {logging_mixin.py:188} INFO - Error fetching Pokémon ID 7: HTTPSConnectionPool(host='pokeapi.co', port=443): Max retries exceeded with url: /api/v2/pokemon/7/ (Caused by NewConnectionError('<urllib3.connection.HTTPSConnection object at 0xffff855ec5c0>: Failed to establish a new connection: [Errno -2] Name or service not known'))
[2025-06-06T09:47:49.966+0000] {logging_mixin.py:188} INFO - Error fetching Pokémon ID 8: HTTPSConnectionPool(host='pokeapi.co', port=443): Max retries exceeded with url: /api/v2/pokemon/8/ (Caused by NewConnectionError('<urllib3.connection.HTTPSConnection object at 0xffff855ec5c0>: Failed to establish a new connection: [Errno -2] Name or service not known'))
[2025-06-06T09:47:49.970+0000] {logging_mixin.py:188} INFO - Error fetching Pokémon ID 9: HTTPSConnectionPool(host='pokeapi.co', port=443): Max retries exceeded with url: /api/v2/pokemon/9/ (Caused by NewConnectionError('<urllib3.connection.HTTPSConnection object at 0xffff855ec860>: Failed to establish a new connection: [Errno -2] Name or service not known'))
[2025-06-06T09:47:49.974+0000] {logging_mixin.py:188} INFO - Error fetching Pokémon ID 10: HTTPSConnectionPool(host='pokeapi.co', port=443): Max retries exceeded with url: /api/v2/pokemon/10/ (Caused by NewConnectionError('<urllib3.connection.HTTPSConnection object at 0xffff855ec860>: Failed to establish a new connection: [Errno -2] Name or service not known'))
[2025-06-06T09:47:49.978+0000] {logging_mixin.py:188} INFO - Error fetching Pokémon ID 11: HTTPSConnectionPool(host='pokeapi.co', port=443): Max retries exceeded with url: /api/v2/pokemon/11/ (Caused by NewConnectionError('<urllib3.connection.HTTPSConnection object at 0xffff855ecc50>: Failed to establish a new connection: [Errno -2] Name or service not known'))
[2025-06-06T09:47:49.981+0000] {logging_mixin.py:188} INFO - Error fetching Pokémon ID 12: HTTPSConnectionPool(host='pokeapi.co', port=443): Max retries exceeded with url: /api/v2/pokemon/12/ (Caused by NewConnectionError('<urllib3.connection.HTTPSConnection object at 0xffff855ed0d0>: Failed to establish a new connection: [Errno -2] Name or service not known'))
[2025-06-06T09:47:49.984+0000] {logging_mixin.py:188} INFO - Error fetching Pokémon ID 13: HTTPSConnectionPool(host='pokeapi.co', port=443): Max retries exceeded with url: /api/v2/pokemon/13/ (Caused by NewConnectionError('<urllib3.connection.HTTPSConnection object at 0xffff855ed070>: Failed to establish a new connection: [Errno -2] Name or service not known'))
[2025-06-06T09:47:49.987+0000] {logging_mixin.py:188} INFO - Error fetching Pokémon ID 14: HTTPSConnectionPool(host='pokeapi.co', port=443): Max retries exceeded with url: /api/v2/pokemon/14/ (Caused by NewConnectionError('<urllib3.connection.HTTPSConnection object at 0xffff855ed0d0>: Failed to establish a new connection: [Errno -2] Name or service not known'))
[2025-06-06T09:47:49.991+0000] {logging_mixin.py:188} INFO - Error fetching Pokémon ID 15: HTTPSConnectionPool(host='pokeapi.co', port=443): Max retries exceeded with url: /api/v2/pokemon/15/ (Caused by NewConnectionError('<urllib3.connection.HTTPSConnection object at 0xffff855ed070>: Failed to establish a new connection: [Errno -2] Name or service not known'))
[2025-06-06T09:47:49.995+0000] {logging_mixin.py:188} INFO - Error fetching Pokémon ID 16: HTTPSConnectionPool(host='pokeapi.co', port=443): Max retries exceeded with url: /api/v2/pokemon/16/ (Caused by NewConnectionError('<urllib3.connection.HTTPSConnection object at 0xffff855ec440>: Failed to establish a new connection: [Errno -2] Name or service not known'))
[2025-06-06T09:47:49.998+0000] {logging_mixin.py:188} INFO - Error fetching Pokémon ID 17: HTTPSConnectionPool(host='pokeapi.co', port=443): Max retries exceeded with url: /api/v2/pokemon/17/ (Caused by NewConnectionError('<urllib3.connection.HTTPSConnection object at 0xffff855ecfb0>: Failed to establish a new connection: [Errno -2] Name or service not known'))
[2025-06-06T09:47:50.003+0000] {logging_mixin.py:188} INFO - Error fetching Pokémon ID 18: HTTPSConnectionPool(host='pokeapi.co', port=443): Max retries exceeded with url: /api/v2/pokemon/18/ (Caused by NewConnectionError('<urllib3.connection.HTTPSConnection object at 0xffff855ec440>: Failed to establish a new connection: [Errno -2] Name or service not known'))
[2025-06-06T09:47:50.006+0000] {logging_mixin.py:188} INFO - Error fetching Pokémon ID 19: HTTPSConnectionPool(host='pokeapi.co', port=443): Max retries exceeded with url: /api/v2/pokemon/19/ (Caused by NewConnectionError('<urllib3.connection.HTTPSConnection object at 0xffff855ec440>: Failed to establish a new connection: [Errno -2] Name or service not known'))
[2025-06-06T09:47:50.007+0000] {python.py:237} INFO - Done. Returned value was: None
[2025-06-06T09:47:50.008+0000] {taskinstance.py:441} INFO - ::group::Post task execution logs
[2025-06-06T09:47:50.015+0000] {taskinstance.py:1205} INFO - Marking task as SUCCESS. dag_id=pokemon_partitioned_to_kafka, task_id=fetch_pokemon_and_send_partitioned_to_kafka, execution_date=20250606T094600, start_date=20250606T094749, end_date=20250606T094750
[2025-06-06T09:47:50.066+0000] {local_task_job_runner.py:240} INFO - Task exited with return code 0
[2025-06-06T09:47:50.078+0000] {taskinstance.py:3482} INFO - 0 downstream tasks scheduled from follow-on schedule check
[2025-06-06T09:47:50.080+0000] {local_task_job_runner.py:222} INFO - ::endgroup::
