[2025-06-06T09:37:39.850+0000] {local_task_job_runner.py:120} INFO - ::group::Pre task execution logs
[2025-06-06T09:37:39.865+0000] {taskinstance.py:2073} INFO - Dependencies all met for dep_context=non-requeueable deps ti=<TaskInstance: pokemon_partitioned_to_kafka.fetch_pokemon_and_send_partitioned_to_kafka scheduled__2025-06-06T09:03:00+00:00 [queued]>
[2025-06-06T09:37:39.869+0000] {taskinstance.py:2073} INFO - Dependencies all met for dep_context=requeueable deps ti=<TaskInstance: pokemon_partitioned_to_kafka.fetch_pokemon_and_send_partitioned_to_kafka scheduled__2025-06-06T09:03:00+00:00 [queued]>
[2025-06-06T09:37:39.870+0000] {taskinstance.py:2303} INFO - Starting attempt 1 of 1
[2025-06-06T09:37:39.877+0000] {taskinstance.py:2327} INFO - Executing <Task(PythonOperator): fetch_pokemon_and_send_partitioned_to_kafka> on 2025-06-06 09:03:00+00:00
[2025-06-06T09:37:39.882+0000] {logging_mixin.py:188} WARNING - /home/***/.local/lib/python3.12/site-packages/***/task/task_runner/standard_task_runner.py:61 DeprecationWarning: This process (pid=1848) is multi-threaded, use of fork() may lead to deadlocks in the child.
[2025-06-06T09:37:39.882+0000] {standard_task_runner.py:63} INFO - Started process 1856 to run task
[2025-06-06T09:37:39.882+0000] {standard_task_runner.py:90} INFO - Running: ['***', 'tasks', 'run', 'pokemon_partitioned_to_kafka', 'fetch_pokemon_and_send_partitioned_to_kafka', 'scheduled__2025-06-06T09:03:00+00:00', '--job-id', '91', '--raw', '--subdir', 'DAGS_FOLDER/pkapi_to_kafka_dag.py', '--cfg-path', '/tmp/tmprtmbhybb']
[2025-06-06T09:37:39.884+0000] {standard_task_runner.py:91} INFO - Job 91: Subtask fetch_pokemon_and_send_partitioned_to_kafka
[2025-06-06T09:37:39.892+0000] {logging_mixin.py:188} WARNING - /home/***/.local/lib/python3.12/site-packages/***/settings.py:195 DeprecationWarning: The sql_alchemy_conn option in [core] has been moved to the sql_alchemy_conn option in [database] - the old setting has been used, but please update your config.
[2025-06-06T09:37:39.913+0000] {task_command.py:426} INFO - Running <TaskInstance: pokemon_partitioned_to_kafka.fetch_pokemon_and_send_partitioned_to_kafka scheduled__2025-06-06T09:03:00+00:00 [running]> on host 856ef77f0083
[2025-06-06T09:37:39.971+0000] {taskinstance.py:2644} INFO - Exporting env vars: AIRFLOW_CTX_DAG_OWNER='***' AIRFLOW_CTX_DAG_ID='pokemon_partitioned_to_kafka' AIRFLOW_CTX_TASK_ID='fetch_pokemon_and_send_partitioned_to_kafka' AIRFLOW_CTX_EXECUTION_DATE='2025-06-06T09:03:00+00:00' AIRFLOW_CTX_TRY_NUMBER='1' AIRFLOW_CTX_DAG_RUN_ID='scheduled__2025-06-06T09:03:00+00:00'
[2025-06-06T09:37:39.972+0000] {taskinstance.py:430} INFO - ::endgroup::
[2025-06-06T09:37:47.989+0000] {logging_mixin.py:188} INFO - Error fetching Pokémon ID 1: HTTPSConnectionPool(host='pokeapi.co', port=443): Max retries exceeded with url: /api/v2/pokemon/1/ (Caused by NewConnectionError('<urllib3.connection.HTTPSConnection object at 0xffff775b68a0>: Failed to establish a new connection: [Errno -3] Temporary failure in name resolution'))
[2025-06-06T09:37:52.419+0000] {logging_mixin.py:188} INFO - Error fetching Pokémon ID 2: HTTPSConnectionPool(host='pokeapi.co', port=443): Max retries exceeded with url: /api/v2/pokemon/2/ (Caused by NewConnectionError('<urllib3.connection.HTTPSConnection object at 0xffff855c7950>: Failed to establish a new connection: [Errno -2] Name or service not known'))
[2025-06-06T09:37:52.448+0000] {logging_mixin.py:188} INFO - Error fetching Pokémon ID 3: HTTPSConnectionPool(host='pokeapi.co', port=443): Max retries exceeded with url: /api/v2/pokemon/3/ (Caused by NewConnectionError('<urllib3.connection.HTTPSConnection object at 0xffff855c77a0>: Failed to establish a new connection: [Errno -2] Name or service not known'))
[2025-06-06T09:37:52.454+0000] {logging_mixin.py:188} INFO - Error fetching Pokémon ID 4: HTTPSConnectionPool(host='pokeapi.co', port=443): Max retries exceeded with url: /api/v2/pokemon/4/ (Caused by NewConnectionError('<urllib3.connection.HTTPSConnection object at 0xffff855c7bc0>: Failed to establish a new connection: [Errno -2] Name or service not known'))
[2025-06-06T09:37:52.459+0000] {logging_mixin.py:188} INFO - Error fetching Pokémon ID 5: HTTPSConnectionPool(host='pokeapi.co', port=443): Max retries exceeded with url: /api/v2/pokemon/5/ (Caused by NewConnectionError('<urllib3.connection.HTTPSConnection object at 0xffff855c7f50>: Failed to establish a new connection: [Errno -2] Name or service not known'))
[2025-06-06T09:37:52.462+0000] {logging_mixin.py:188} INFO - Error fetching Pokémon ID 6: HTTPSConnectionPool(host='pokeapi.co', port=443): Max retries exceeded with url: /api/v2/pokemon/6/ (Caused by NewConnectionError('<urllib3.connection.HTTPSConnection object at 0xffff8c4a9130>: Failed to establish a new connection: [Errno -2] Name or service not known'))
[2025-06-06T09:37:52.476+0000] {logging_mixin.py:188} INFO - Error fetching Pokémon ID 7: HTTPSConnectionPool(host='pokeapi.co', port=443): Max retries exceeded with url: /api/v2/pokemon/7/ (Caused by NewConnectionError('<urllib3.connection.HTTPSConnection object at 0xffff855ec440>: Failed to establish a new connection: [Errno -2] Name or service not known'))
[2025-06-06T09:37:52.481+0000] {logging_mixin.py:188} INFO - Error fetching Pokémon ID 8: HTTPSConnectionPool(host='pokeapi.co', port=443): Max retries exceeded with url: /api/v2/pokemon/8/ (Caused by NewConnectionError('<urllib3.connection.HTTPSConnection object at 0xffff855ec410>: Failed to establish a new connection: [Errno -2] Name or service not known'))
[2025-06-06T09:37:52.484+0000] {logging_mixin.py:188} INFO - Error fetching Pokémon ID 9: HTTPSConnectionPool(host='pokeapi.co', port=443): Max retries exceeded with url: /api/v2/pokemon/9/ (Caused by NewConnectionError('<urllib3.connection.HTTPSConnection object at 0xffff855ec860>: Failed to establish a new connection: [Errno -2] Name or service not known'))
[2025-06-06T09:37:52.490+0000] {logging_mixin.py:188} INFO - Error fetching Pokémon ID 10: HTTPSConnectionPool(host='pokeapi.co', port=443): Max retries exceeded with url: /api/v2/pokemon/10/ (Caused by NewConnectionError('<urllib3.connection.HTTPSConnection object at 0xffff855ec860>: Failed to establish a new connection: [Errno -2] Name or service not known'))
[2025-06-06T09:37:52.506+0000] {logging_mixin.py:188} INFO - Error fetching Pokémon ID 11: HTTPSConnectionPool(host='pokeapi.co', port=443): Max retries exceeded with url: /api/v2/pokemon/11/ (Caused by NewConnectionError('<urllib3.connection.HTTPSConnection object at 0xffff855ec860>: Failed to establish a new connection: [Errno -2] Name or service not known'))
[2025-06-06T09:37:52.509+0000] {logging_mixin.py:188} INFO - Error fetching Pokémon ID 12: HTTPSConnectionPool(host='pokeapi.co', port=443): Max retries exceeded with url: /api/v2/pokemon/12/ (Caused by NewConnectionError('<urllib3.connection.HTTPSConnection object at 0xffff855ec860>: Failed to establish a new connection: [Errno -2] Name or service not known'))
[2025-06-06T09:37:52.512+0000] {logging_mixin.py:188} INFO - Error fetching Pokémon ID 13: HTTPSConnectionPool(host='pokeapi.co', port=443): Max retries exceeded with url: /api/v2/pokemon/13/ (Caused by NewConnectionError('<urllib3.connection.HTTPSConnection object at 0xffff855ec860>: Failed to establish a new connection: [Errno -2] Name or service not known'))
[2025-06-06T09:37:52.515+0000] {logging_mixin.py:188} INFO - Error fetching Pokémon ID 14: HTTPSConnectionPool(host='pokeapi.co', port=443): Max retries exceeded with url: /api/v2/pokemon/14/ (Caused by NewConnectionError('<urllib3.connection.HTTPSConnection object at 0xffff855ec170>: Failed to establish a new connection: [Errno -2] Name or service not known'))
[2025-06-06T09:37:52.518+0000] {logging_mixin.py:188} INFO - Error fetching Pokémon ID 15: HTTPSConnectionPool(host='pokeapi.co', port=443): Max retries exceeded with url: /api/v2/pokemon/15/ (Caused by NewConnectionError('<urllib3.connection.HTTPSConnection object at 0xffff855ec170>: Failed to establish a new connection: [Errno -2] Name or service not known'))
[2025-06-06T09:37:52.521+0000] {logging_mixin.py:188} INFO - Error fetching Pokémon ID 16: HTTPSConnectionPool(host='pokeapi.co', port=443): Max retries exceeded with url: /api/v2/pokemon/16/ (Caused by NewConnectionError('<urllib3.connection.HTTPSConnection object at 0xffff855ece90>: Failed to establish a new connection: [Errno -2] Name or service not known'))
[2025-06-06T09:37:52.525+0000] {logging_mixin.py:188} INFO - Error fetching Pokémon ID 17: HTTPSConnectionPool(host='pokeapi.co', port=443): Max retries exceeded with url: /api/v2/pokemon/17/ (Caused by NewConnectionError('<urllib3.connection.HTTPSConnection object at 0xffff855ed280>: Failed to establish a new connection: [Errno -2] Name or service not known'))
[2025-06-06T09:37:52.529+0000] {logging_mixin.py:188} INFO - Error fetching Pokémon ID 18: HTTPSConnectionPool(host='pokeapi.co', port=443): Max retries exceeded with url: /api/v2/pokemon/18/ (Caused by NewConnectionError('<urllib3.connection.HTTPSConnection object at 0xffff855ec860>: Failed to establish a new connection: [Errno -2] Name or service not known'))
[2025-06-06T09:37:52.535+0000] {logging_mixin.py:188} INFO - Error fetching Pokémon ID 19: HTTPSConnectionPool(host='pokeapi.co', port=443): Max retries exceeded with url: /api/v2/pokemon/19/ (Caused by NewConnectionError('<urllib3.connection.HTTPSConnection object at 0xffff855ece90>: Failed to establish a new connection: [Errno -2] Name or service not known'))
[2025-06-06T09:37:52.536+0000] {python.py:237} INFO - Done. Returned value was: None
[2025-06-06T09:37:52.538+0000] {taskinstance.py:441} INFO - ::group::Post task execution logs
[2025-06-06T09:37:52.544+0000] {taskinstance.py:1205} INFO - Marking task as SUCCESS. dag_id=pokemon_partitioned_to_kafka, task_id=fetch_pokemon_and_send_partitioned_to_kafka, execution_date=20250606T090300, start_date=20250606T093739, end_date=20250606T093752
[2025-06-06T09:37:52.569+0000] {local_task_job_runner.py:240} INFO - Task exited with return code 0
[2025-06-06T09:37:52.579+0000] {taskinstance.py:3482} INFO - 0 downstream tasks scheduled from follow-on schedule check
[2025-06-06T09:37:52.580+0000] {local_task_job_runner.py:222} INFO - ::endgroup::
