[2025-06-06T09:48:00.598+0000] {local_task_job_runner.py:120} INFO - ::group::Pre task execution logs
[2025-06-06T09:48:00.612+0000] {taskinstance.py:2073} INFO - Dependencies all met for dep_context=non-requeueable deps ti=<TaskInstance: pokemon_partitioned_to_kafka.fetch_pokemon_and_send_partitioned_to_kafka scheduled__2025-06-06T09:47:00+00:00 [queued]>
[2025-06-06T09:48:00.615+0000] {taskinstance.py:2073} INFO - Dependencies all met for dep_context=requeueable deps ti=<TaskInstance: pokemon_partitioned_to_kafka.fetch_pokemon_and_send_partitioned_to_kafka scheduled__2025-06-06T09:47:00+00:00 [queued]>
[2025-06-06T09:48:00.615+0000] {taskinstance.py:2303} INFO - Starting attempt 1 of 1
[2025-06-06T09:48:00.621+0000] {taskinstance.py:2327} INFO - Executing <Task(PythonOperator): fetch_pokemon_and_send_partitioned_to_kafka> on 2025-06-06 09:47:00+00:00
[2025-06-06T09:48:00.624+0000] {logging_mixin.py:188} WARNING - /home/***/.local/lib/python3.12/site-packages/***/task/task_runner/standard_task_runner.py:61 DeprecationWarning: This process (pid=1898) is multi-threaded, use of fork() may lead to deadlocks in the child.
[2025-06-06T09:48:00.625+0000] {standard_task_runner.py:63} INFO - Started process 1899 to run task
[2025-06-06T09:48:00.625+0000] {standard_task_runner.py:90} INFO - Running: ['***', 'tasks', 'run', 'pokemon_partitioned_to_kafka', 'fetch_pokemon_and_send_partitioned_to_kafka', 'scheduled__2025-06-06T09:47:00+00:00', '--job-id', '96', '--raw', '--subdir', 'DAGS_FOLDER/pkapi_to_kafka_dag.py', '--cfg-path', '/tmp/tmpf8qgdcxf']
[2025-06-06T09:48:00.626+0000] {standard_task_runner.py:91} INFO - Job 96: Subtask fetch_pokemon_and_send_partitioned_to_kafka
[2025-06-06T09:48:00.634+0000] {logging_mixin.py:188} WARNING - /home/***/.local/lib/python3.12/site-packages/***/settings.py:195 DeprecationWarning: The sql_alchemy_conn option in [core] has been moved to the sql_alchemy_conn option in [database] - the old setting has been used, but please update your config.
[2025-06-06T09:48:00.651+0000] {task_command.py:426} INFO - Running <TaskInstance: pokemon_partitioned_to_kafka.fetch_pokemon_and_send_partitioned_to_kafka scheduled__2025-06-06T09:47:00+00:00 [running]> on host 856ef77f0083
[2025-06-06T09:48:00.693+0000] {taskinstance.py:2644} INFO - Exporting env vars: AIRFLOW_CTX_DAG_OWNER='***' AIRFLOW_CTX_DAG_ID='pokemon_partitioned_to_kafka' AIRFLOW_CTX_TASK_ID='fetch_pokemon_and_send_partitioned_to_kafka' AIRFLOW_CTX_EXECUTION_DATE='2025-06-06T09:47:00+00:00' AIRFLOW_CTX_TRY_NUMBER='1' AIRFLOW_CTX_DAG_RUN_ID='scheduled__2025-06-06T09:47:00+00:00'
[2025-06-06T09:48:00.693+0000] {taskinstance.py:430} INFO - ::endgroup::
[2025-06-06T09:48:00.705+0000] {logging_mixin.py:188} INFO - Error fetching Pokémon ID 1: HTTPSConnectionPool(host='pokeapi.co', port=443): Max retries exceeded with url: /api/v2/pokemon/1/ (Caused by NewConnectionError('<urllib3.connection.HTTPSConnection object at 0xffff858096a0>: Failed to establish a new connection: [Errno -2] Name or service not known'))
[2025-06-06T09:48:00.708+0000] {logging_mixin.py:188} INFO - Error fetching Pokémon ID 2: HTTPSConnectionPool(host='pokeapi.co', port=443): Max retries exceeded with url: /api/v2/pokemon/2/ (Caused by NewConnectionError('<urllib3.connection.HTTPSConnection object at 0xffff855beab0>: Failed to establish a new connection: [Errno -2] Name or service not known'))
[2025-06-06T09:48:00.710+0000] {logging_mixin.py:188} INFO - Error fetching Pokémon ID 3: HTTPSConnectionPool(host='pokeapi.co', port=443): Max retries exceeded with url: /api/v2/pokemon/3/ (Caused by NewConnectionError('<urllib3.connection.HTTPSConnection object at 0xffff855beab0>: Failed to establish a new connection: [Errno -2] Name or service not known'))
[2025-06-06T09:48:00.713+0000] {logging_mixin.py:188} INFO - Error fetching Pokémon ID 4: HTTPSConnectionPool(host='pokeapi.co', port=443): Max retries exceeded with url: /api/v2/pokemon/4/ (Caused by NewConnectionError('<urllib3.connection.HTTPSConnection object at 0xffff855be930>: Failed to establish a new connection: [Errno -2] Name or service not known'))
[2025-06-06T09:48:00.716+0000] {logging_mixin.py:188} INFO - Error fetching Pokémon ID 5: HTTPSConnectionPool(host='pokeapi.co', port=443): Max retries exceeded with url: /api/v2/pokemon/5/ (Caused by NewConnectionError('<urllib3.connection.HTTPSConnection object at 0xffff855bec90>: Failed to establish a new connection: [Errno -2] Name or service not known'))
[2025-06-06T09:48:00.719+0000] {logging_mixin.py:188} INFO - Error fetching Pokémon ID 6: HTTPSConnectionPool(host='pokeapi.co', port=443): Max retries exceeded with url: /api/v2/pokemon/6/ (Caused by NewConnectionError('<urllib3.connection.HTTPSConnection object at 0xffff855be840>: Failed to establish a new connection: [Errno -2] Name or service not known'))
[2025-06-06T09:48:00.721+0000] {logging_mixin.py:188} INFO - Error fetching Pokémon ID 7: HTTPSConnectionPool(host='pokeapi.co', port=443): Max retries exceeded with url: /api/v2/pokemon/7/ (Caused by NewConnectionError('<urllib3.connection.HTTPSConnection object at 0xffff855bfd10>: Failed to establish a new connection: [Errno -2] Name or service not known'))
[2025-06-06T09:48:00.724+0000] {logging_mixin.py:188} INFO - Error fetching Pokémon ID 8: HTTPSConnectionPool(host='pokeapi.co', port=443): Max retries exceeded with url: /api/v2/pokemon/8/ (Caused by NewConnectionError('<urllib3.connection.HTTPSConnection object at 0xffff855bfec0>: Failed to establish a new connection: [Errno -2] Name or service not known'))
[2025-06-06T09:48:00.726+0000] {logging_mixin.py:188} INFO - Error fetching Pokémon ID 9: HTTPSConnectionPool(host='pokeapi.co', port=443): Max retries exceeded with url: /api/v2/pokemon/9/ (Caused by NewConnectionError('<urllib3.connection.HTTPSConnection object at 0xffff775af530>: Failed to establish a new connection: [Errno -2] Name or service not known'))
[2025-06-06T09:48:00.728+0000] {logging_mixin.py:188} INFO - Error fetching Pokémon ID 10: HTTPSConnectionPool(host='pokeapi.co', port=443): Max retries exceeded with url: /api/v2/pokemon/10/ (Caused by NewConnectionError('<urllib3.connection.HTTPSConnection object at 0xffff79f685c0>: Failed to establish a new connection: [Errno -2] Name or service not known'))
[2025-06-06T09:48:00.731+0000] {logging_mixin.py:188} INFO - Error fetching Pokémon ID 11: HTTPSConnectionPool(host='pokeapi.co', port=443): Max retries exceeded with url: /api/v2/pokemon/11/ (Caused by NewConnectionError('<urllib3.connection.HTTPSConnection object at 0xffff853f84d0>: Failed to establish a new connection: [Errno -2] Name or service not known'))
[2025-06-06T09:48:00.734+0000] {logging_mixin.py:188} INFO - Error fetching Pokémon ID 12: HTTPSConnectionPool(host='pokeapi.co', port=443): Max retries exceeded with url: /api/v2/pokemon/12/ (Caused by NewConnectionError('<urllib3.connection.HTTPSConnection object at 0xffff853f87a0>: Failed to establish a new connection: [Errno -2] Name or service not known'))
[2025-06-06T09:48:00.736+0000] {logging_mixin.py:188} INFO - Error fetching Pokémon ID 13: HTTPSConnectionPool(host='pokeapi.co', port=443): Max retries exceeded with url: /api/v2/pokemon/13/ (Caused by NewConnectionError('<urllib3.connection.HTTPSConnection object at 0xffff853f89b0>: Failed to establish a new connection: [Errno -2] Name or service not known'))
[2025-06-06T09:48:00.738+0000] {logging_mixin.py:188} INFO - Error fetching Pokémon ID 14: HTTPSConnectionPool(host='pokeapi.co', port=443): Max retries exceeded with url: /api/v2/pokemon/14/ (Caused by NewConnectionError('<urllib3.connection.HTTPSConnection object at 0xffff853f8950>: Failed to establish a new connection: [Errno -2] Name or service not known'))
[2025-06-06T09:48:00.740+0000] {logging_mixin.py:188} INFO - Error fetching Pokémon ID 15: HTTPSConnectionPool(host='pokeapi.co', port=443): Max retries exceeded with url: /api/v2/pokemon/15/ (Caused by NewConnectionError('<urllib3.connection.HTTPSConnection object at 0xffff853f8950>: Failed to establish a new connection: [Errno -2] Name or service not known'))
[2025-06-06T09:48:00.743+0000] {logging_mixin.py:188} INFO - Error fetching Pokémon ID 16: HTTPSConnectionPool(host='pokeapi.co', port=443): Max retries exceeded with url: /api/v2/pokemon/16/ (Caused by NewConnectionError('<urllib3.connection.HTTPSConnection object at 0xffff853f8950>: Failed to establish a new connection: [Errno -2] Name or service not known'))
[2025-06-06T09:48:00.745+0000] {logging_mixin.py:188} INFO - Error fetching Pokémon ID 17: HTTPSConnectionPool(host='pokeapi.co', port=443): Max retries exceeded with url: /api/v2/pokemon/17/ (Caused by NewConnectionError('<urllib3.connection.HTTPSConnection object at 0xffff853f8ef0>: Failed to establish a new connection: [Errno -2] Name or service not known'))
[2025-06-06T09:48:00.747+0000] {logging_mixin.py:188} INFO - Error fetching Pokémon ID 18: HTTPSConnectionPool(host='pokeapi.co', port=443): Max retries exceeded with url: /api/v2/pokemon/18/ (Caused by NewConnectionError('<urllib3.connection.HTTPSConnection object at 0xffff853f8ef0>: Failed to establish a new connection: [Errno -2] Name or service not known'))
[2025-06-06T09:48:00.750+0000] {logging_mixin.py:188} INFO - Error fetching Pokémon ID 19: HTTPSConnectionPool(host='pokeapi.co', port=443): Max retries exceeded with url: /api/v2/pokemon/19/ (Caused by NewConnectionError('<urllib3.connection.HTTPSConnection object at 0xffff853f8320>: Failed to establish a new connection: [Errno -2] Name or service not known'))
[2025-06-06T09:48:00.750+0000] {python.py:237} INFO - Done. Returned value was: None
[2025-06-06T09:48:00.751+0000] {taskinstance.py:441} INFO - ::group::Post task execution logs
[2025-06-06T09:48:00.756+0000] {taskinstance.py:1205} INFO - Marking task as SUCCESS. dag_id=pokemon_partitioned_to_kafka, task_id=fetch_pokemon_and_send_partitioned_to_kafka, execution_date=20250606T094700, start_date=20250606T094800, end_date=20250606T094800
[2025-06-06T09:48:00.766+0000] {local_task_job_runner.py:240} INFO - Task exited with return code 0
[2025-06-06T09:48:00.774+0000] {taskinstance.py:3482} INFO - 0 downstream tasks scheduled from follow-on schedule check
[2025-06-06T09:48:00.775+0000] {local_task_job_runner.py:222} INFO - ::endgroup::
