[2025-06-06T14:36:55.368+0000] {local_task_job_runner.py:120} INFO - ::group::Pre task execution logs
[2025-06-06T14:36:55.384+0000] {taskinstance.py:2073} INFO - Dependencies all met for dep_context=non-requeueable deps ti=<TaskInstance: pokemon_partitioned_to_kafka.fetch_pokemon_and_send_partitioned_to_kafka scheduled__2025-06-06T14:07:00+00:00 [queued]>
[2025-06-06T14:36:55.388+0000] {taskinstance.py:2073} INFO - Dependencies all met for dep_context=requeueable deps ti=<TaskInstance: pokemon_partitioned_to_kafka.fetch_pokemon_and_send_partitioned_to_kafka scheduled__2025-06-06T14:07:00+00:00 [queued]>
[2025-06-06T14:36:55.388+0000] {taskinstance.py:2303} INFO - Starting attempt 1 of 1
[2025-06-06T14:36:55.395+0000] {taskinstance.py:2327} INFO - Executing <Task(PythonOperator): fetch_pokemon_and_send_partitioned_to_kafka> on 2025-06-06 14:07:00+00:00
[2025-06-06T14:36:55.399+0000] {logging_mixin.py:188} WARNING - /home/***/.local/lib/python3.12/site-packages/***/task/task_runner/standard_task_runner.py:61 DeprecationWarning: This process (pid=2067) is multi-threaded, use of fork() may lead to deadlocks in the child.
[2025-06-06T14:36:55.399+0000] {standard_task_runner.py:63} INFO - Started process 2069 to run task
[2025-06-06T14:36:55.399+0000] {standard_task_runner.py:90} INFO - Running: ['***', 'tasks', 'run', 'pokemon_partitioned_to_kafka', 'fetch_pokemon_and_send_partitioned_to_kafka', 'scheduled__2025-06-06T14:07:00+00:00', '--job-id', '109', '--raw', '--subdir', 'DAGS_FOLDER/pkapi_to_kafka_dag.py', '--cfg-path', '/tmp/tmpcyu64f28']
[2025-06-06T14:36:55.400+0000] {standard_task_runner.py:91} INFO - Job 109: Subtask fetch_pokemon_and_send_partitioned_to_kafka
[2025-06-06T14:36:55.410+0000] {logging_mixin.py:188} WARNING - /home/***/.local/lib/python3.12/site-packages/***/settings.py:195 DeprecationWarning: The sql_alchemy_conn option in [core] has been moved to the sql_alchemy_conn option in [database] - the old setting has been used, but please update your config.
[2025-06-06T14:36:55.435+0000] {task_command.py:426} INFO - Running <TaskInstance: pokemon_partitioned_to_kafka.fetch_pokemon_and_send_partitioned_to_kafka scheduled__2025-06-06T14:07:00+00:00 [running]> on host 856ef77f0083
[2025-06-06T14:36:55.497+0000] {taskinstance.py:2644} INFO - Exporting env vars: AIRFLOW_CTX_DAG_OWNER='***' AIRFLOW_CTX_DAG_ID='pokemon_partitioned_to_kafka' AIRFLOW_CTX_TASK_ID='fetch_pokemon_and_send_partitioned_to_kafka' AIRFLOW_CTX_EXECUTION_DATE='2025-06-06T14:07:00+00:00' AIRFLOW_CTX_TRY_NUMBER='1' AIRFLOW_CTX_DAG_RUN_ID='scheduled__2025-06-06T14:07:00+00:00'
[2025-06-06T14:36:55.498+0000] {taskinstance.py:430} INFO - ::endgroup::
[2025-06-06T14:36:55.516+0000] {logging_mixin.py:188} INFO - Error fetching Pokémon ID 1: HTTPSConnectionPool(host='pokeapi.co', port=443): Max retries exceeded with url: /api/v2/pokemon/1/ (Caused by NewConnectionError('<urllib3.connection.HTTPSConnection object at 0xffff79f68a40>: Failed to establish a new connection: [Errno -2] Name or service not known'))
[2025-06-06T14:36:55.526+0000] {logging_mixin.py:188} INFO - Error fetching Pokémon ID 2: HTTPSConnectionPool(host='pokeapi.co', port=443): Max retries exceeded with url: /api/v2/pokemon/2/ (Caused by NewConnectionError('<urllib3.connection.HTTPSConnection object at 0xffff855bb140>: Failed to establish a new connection: [Errno -2] Name or service not known'))
[2025-06-06T14:36:55.533+0000] {logging_mixin.py:188} INFO - Error fetching Pokémon ID 3: HTTPSConnectionPool(host='pokeapi.co', port=443): Max retries exceeded with url: /api/v2/pokemon/3/ (Caused by NewConnectionError('<urllib3.connection.HTTPSConnection object at 0xffff855baed0>: Failed to establish a new connection: [Errno -2] Name or service not known'))
[2025-06-06T14:36:55.539+0000] {logging_mixin.py:188} INFO - Error fetching Pokémon ID 4: HTTPSConnectionPool(host='pokeapi.co', port=443): Max retries exceeded with url: /api/v2/pokemon/4/ (Caused by NewConnectionError('<urllib3.connection.HTTPSConnection object at 0xffff855bb530>: Failed to establish a new connection: [Errno -2] Name or service not known'))
[2025-06-06T14:36:55.548+0000] {logging_mixin.py:188} INFO - Error fetching Pokémon ID 5: HTTPSConnectionPool(host='pokeapi.co', port=443): Max retries exceeded with url: /api/v2/pokemon/5/ (Caused by NewConnectionError('<urllib3.connection.HTTPSConnection object at 0xffff855bab10>: Failed to establish a new connection: [Errno -2] Name or service not known'))
[2025-06-06T14:36:55.553+0000] {logging_mixin.py:188} INFO - Error fetching Pokémon ID 6: HTTPSConnectionPool(host='pokeapi.co', port=443): Max retries exceeded with url: /api/v2/pokemon/6/ (Caused by NewConnectionError('<urllib3.connection.HTTPSConnection object at 0xffff855bb950>: Failed to establish a new connection: [Errno -2] Name or service not known'))
[2025-06-06T14:36:55.557+0000] {logging_mixin.py:188} INFO - Error fetching Pokémon ID 7: HTTPSConnectionPool(host='pokeapi.co', port=443): Max retries exceeded with url: /api/v2/pokemon/7/ (Caused by NewConnectionError('<urllib3.connection.HTTPSConnection object at 0xffff855bac60>: Failed to establish a new connection: [Errno -2] Name or service not known'))
[2025-06-06T14:36:55.564+0000] {logging_mixin.py:188} INFO - Error fetching Pokémon ID 8: HTTPSConnectionPool(host='pokeapi.co', port=443): Max retries exceeded with url: /api/v2/pokemon/8/ (Caused by NewConnectionError('<urllib3.connection.HTTPSConnection object at 0xffff855bbfb0>: Failed to establish a new connection: [Errno -2] Name or service not known'))
[2025-06-06T14:36:55.569+0000] {logging_mixin.py:188} INFO - Error fetching Pokémon ID 9: HTTPSConnectionPool(host='pokeapi.co', port=443): Max retries exceeded with url: /api/v2/pokemon/9/ (Caused by NewConnectionError('<urllib3.connection.HTTPSConnection object at 0xffff855ba090>: Failed to establish a new connection: [Errno -2] Name or service not known'))
[2025-06-06T14:36:55.574+0000] {logging_mixin.py:188} INFO - Error fetching Pokémon ID 10: HTTPSConnectionPool(host='pokeapi.co', port=443): Max retries exceeded with url: /api/v2/pokemon/10/ (Caused by NewConnectionError('<urllib3.connection.HTTPSConnection object at 0xffff85400350>: Failed to establish a new connection: [Errno -2] Name or service not known'))
[2025-06-06T14:36:55.580+0000] {logging_mixin.py:188} INFO - Error fetching Pokémon ID 11: HTTPSConnectionPool(host='pokeapi.co', port=443): Max retries exceeded with url: /api/v2/pokemon/11/ (Caused by NewConnectionError('<urllib3.connection.HTTPSConnection object at 0xffff85400350>: Failed to establish a new connection: [Errno -2] Name or service not known'))
[2025-06-06T14:36:55.584+0000] {logging_mixin.py:188} INFO - Error fetching Pokémon ID 12: HTTPSConnectionPool(host='pokeapi.co', port=443): Max retries exceeded with url: /api/v2/pokemon/12/ (Caused by NewConnectionError('<urllib3.connection.HTTPSConnection object at 0xffff85400950>: Failed to establish a new connection: [Errno -2] Name or service not known'))
[2025-06-06T14:36:55.589+0000] {logging_mixin.py:188} INFO - Error fetching Pokémon ID 13: HTTPSConnectionPool(host='pokeapi.co', port=443): Max retries exceeded with url: /api/v2/pokemon/13/ (Caused by NewConnectionError('<urllib3.connection.HTTPSConnection object at 0xffff85400d40>: Failed to establish a new connection: [Errno -2] Name or service not known'))
[2025-06-06T14:36:55.594+0000] {logging_mixin.py:188} INFO - Error fetching Pokémon ID 14: HTTPSConnectionPool(host='pokeapi.co', port=443): Max retries exceeded with url: /api/v2/pokemon/14/ (Caused by NewConnectionError('<urllib3.connection.HTTPSConnection object at 0xffff85400d40>: Failed to establish a new connection: [Errno -2] Name or service not known'))
[2025-06-06T14:36:55.598+0000] {logging_mixin.py:188} INFO - Error fetching Pokémon ID 15: HTTPSConnectionPool(host='pokeapi.co', port=443): Max retries exceeded with url: /api/v2/pokemon/15/ (Caused by NewConnectionError('<urllib3.connection.HTTPSConnection object at 0xffff85400d40>: Failed to establish a new connection: [Errno -2] Name or service not known'))
[2025-06-06T14:36:55.602+0000] {logging_mixin.py:188} INFO - Error fetching Pokémon ID 16: HTTPSConnectionPool(host='pokeapi.co', port=443): Max retries exceeded with url: /api/v2/pokemon/16/ (Caused by NewConnectionError('<urllib3.connection.HTTPSConnection object at 0xffff854010a0>: Failed to establish a new connection: [Errno -2] Name or service not known'))
[2025-06-06T14:36:55.605+0000] {logging_mixin.py:188} INFO - Error fetching Pokémon ID 17: HTTPSConnectionPool(host='pokeapi.co', port=443): Max retries exceeded with url: /api/v2/pokemon/17/ (Caused by NewConnectionError('<urllib3.connection.HTTPSConnection object at 0xffff85400d40>: Failed to establish a new connection: [Errno -2] Name or service not known'))
[2025-06-06T14:36:55.614+0000] {logging_mixin.py:188} INFO - Error fetching Pokémon ID 18: HTTPSConnectionPool(host='pokeapi.co', port=443): Max retries exceeded with url: /api/v2/pokemon/18/ (Caused by NewConnectionError('<urllib3.connection.HTTPSConnection object at 0xffff854011c0>: Failed to establish a new connection: [Errno -2] Name or service not known'))
[2025-06-06T14:36:55.618+0000] {logging_mixin.py:188} INFO - Error fetching Pokémon ID 19: HTTPSConnectionPool(host='pokeapi.co', port=443): Max retries exceeded with url: /api/v2/pokemon/19/ (Caused by NewConnectionError('<urllib3.connection.HTTPSConnection object at 0xffff85401340>: Failed to establish a new connection: [Errno -2] Name or service not known'))
[2025-06-06T14:36:55.619+0000] {python.py:237} INFO - Done. Returned value was: None
[2025-06-06T14:36:55.619+0000] {taskinstance.py:441} INFO - ::group::Post task execution logs
[2025-06-06T14:36:55.627+0000] {taskinstance.py:1205} INFO - Marking task as SUCCESS. dag_id=pokemon_partitioned_to_kafka, task_id=fetch_pokemon_and_send_partitioned_to_kafka, execution_date=20250606T140700, start_date=20250606T143655, end_date=20250606T143655
[2025-06-06T14:36:55.659+0000] {local_task_job_runner.py:240} INFO - Task exited with return code 0
[2025-06-06T14:36:55.676+0000] {taskinstance.py:3482} INFO - 0 downstream tasks scheduled from follow-on schedule check
[2025-06-06T14:36:55.678+0000] {local_task_job_runner.py:222} INFO - ::endgroup::
