[2025-06-05T23:12:00.331+0000] {local_task_job_runner.py:120} INFO - ::group::Pre task execution logs
[2025-06-05T23:12:00.346+0000] {taskinstance.py:2073} INFO - Dependencies all met for dep_context=non-requeueable deps ti=<TaskInstance: swapi_to_kafka_dag.fetch_swapi_and_send_to_kafka scheduled__2025-06-05T23:10:00+00:00 [queued]>
[2025-06-05T23:12:00.350+0000] {taskinstance.py:2073} INFO - Dependencies all met for dep_context=requeueable deps ti=<TaskInstance: swapi_to_kafka_dag.fetch_swapi_and_send_to_kafka scheduled__2025-06-05T23:10:00+00:00 [queued]>
[2025-06-05T23:12:00.350+0000] {taskinstance.py:2303} INFO - Starting attempt 1 of 1
[2025-06-05T23:12:00.356+0000] {taskinstance.py:2327} INFO - Executing <Task(PythonOperator): fetch_swapi_and_send_to_kafka> on 2025-06-05 23:10:00+00:00
[2025-06-05T23:12:00.360+0000] {logging_mixin.py:188} WARNING - /home/***/.local/lib/python3.12/site-packages/***/task/task_runner/standard_task_runner.py:61 DeprecationWarning: This process (pid=190) is multi-threaded, use of fork() may lead to deadlocks in the child.
[2025-06-05T23:12:00.360+0000] {standard_task_runner.py:63} INFO - Started process 191 to run task
[2025-06-05T23:12:00.360+0000] {standard_task_runner.py:90} INFO - Running: ['***', 'tasks', 'run', 'swapi_to_kafka_dag', 'fetch_swapi_and_send_to_kafka', 'scheduled__2025-06-05T23:10:00+00:00', '--job-id', '4', '--raw', '--subdir', 'DAGS_FOLDER/swapi_to_kafka_dag.py', '--cfg-path', '/tmp/tmpnsskmy14']
[2025-06-05T23:12:00.361+0000] {standard_task_runner.py:91} INFO - Job 4: Subtask fetch_swapi_and_send_to_kafka
[2025-06-05T23:12:00.369+0000] {logging_mixin.py:188} WARNING - /home/***/.local/lib/python3.12/site-packages/***/settings.py:195 DeprecationWarning: The sql_alchemy_conn option in [core] has been moved to the sql_alchemy_conn option in [database] - the old setting has been used, but please update your config.
[2025-06-05T23:12:00.388+0000] {task_command.py:426} INFO - Running <TaskInstance: swapi_to_kafka_dag.fetch_swapi_and_send_to_kafka scheduled__2025-06-05T23:10:00+00:00 [running]> on host e2db4121f8e1
[2025-06-05T23:12:00.429+0000] {taskinstance.py:2644} INFO - Exporting env vars: AIRFLOW_CTX_DAG_OWNER='***' AIRFLOW_CTX_DAG_ID='swapi_to_kafka_dag' AIRFLOW_CTX_TASK_ID='fetch_swapi_and_send_to_kafka' AIRFLOW_CTX_EXECUTION_DATE='2025-06-05T23:10:00+00:00' AIRFLOW_CTX_TRY_NUMBER='1' AIRFLOW_CTX_DAG_RUN_ID='scheduled__2025-06-05T23:10:00+00:00'
[2025-06-05T23:12:00.430+0000] {taskinstance.py:430} INFO - ::endgroup::
[2025-06-05T23:12:00.830+0000] {taskinstance.py:441} INFO - ::group::Post task execution logs
[2025-06-05T23:12:00.831+0000] {taskinstance.py:2890} ERROR - Task failed with exception
Traceback (most recent call last):
  File "/home/airflow/.local/lib/python3.12/site-packages/urllib3/connectionpool.py", line 715, in urlopen
    httplib_response = self._make_request(
                       ^^^^^^^^^^^^^^^^^^^
  File "/home/airflow/.local/lib/python3.12/site-packages/urllib3/connectionpool.py", line 404, in _make_request
    self._validate_conn(conn)
  File "/home/airflow/.local/lib/python3.12/site-packages/urllib3/connectionpool.py", line 1058, in _validate_conn
    conn.connect()
  File "/home/airflow/.local/lib/python3.12/site-packages/urllib3/connection.py", line 419, in connect
    self.sock = ssl_wrap_socket(
                ^^^^^^^^^^^^^^^^
  File "/home/airflow/.local/lib/python3.12/site-packages/urllib3/util/ssl_.py", line 449, in ssl_wrap_socket
    ssl_sock = _ssl_wrap_socket_impl(
               ^^^^^^^^^^^^^^^^^^^^^^
  File "/home/airflow/.local/lib/python3.12/site-packages/urllib3/util/ssl_.py", line 493, in _ssl_wrap_socket_impl
    return ssl_context.wrap_socket(sock, server_hostname=server_hostname)
           ^^^^^^^^^^^^^^^^^^^^^^^^^^^^^^^^^^^^^^^^^^^^^^^^^^^^^^^^^^^^^^
  File "/usr/local/lib/python3.12/ssl.py", line 455, in wrap_socket
    return self.sslsocket_class._create(
           ^^^^^^^^^^^^^^^^^^^^^^^^^^^^^
  File "/usr/local/lib/python3.12/ssl.py", line 1042, in _create
    self.do_handshake()
  File "/usr/local/lib/python3.12/ssl.py", line 1320, in do_handshake
    self._sslobj.do_handshake()
ssl.SSLCertVerificationError: [SSL: CERTIFICATE_VERIFY_FAILED] certificate verify failed: certificate has expired (_ssl.c:1000)

During handling of the above exception, another exception occurred:

Traceback (most recent call last):
  File "/home/airflow/.local/lib/python3.12/site-packages/requests/adapters.py", line 486, in send
    resp = conn.urlopen(
           ^^^^^^^^^^^^^
  File "/home/airflow/.local/lib/python3.12/site-packages/urllib3/connectionpool.py", line 799, in urlopen
    retries = retries.increment(
              ^^^^^^^^^^^^^^^^^^
  File "/home/airflow/.local/lib/python3.12/site-packages/urllib3/util/retry.py", line 592, in increment
    raise MaxRetryError(_pool, url, error or ResponseError(cause))
urllib3.exceptions.MaxRetryError: HTTPSConnectionPool(host='swapi.dev', port=443): Max retries exceeded with url: /api/people/1/ (Caused by SSLError(SSLCertVerificationError(1, '[SSL: CERTIFICATE_VERIFY_FAILED] certificate verify failed: certificate has expired (_ssl.c:1000)')))

During handling of the above exception, another exception occurred:

Traceback (most recent call last):
  File "/home/airflow/.local/lib/python3.12/site-packages/airflow/models/taskinstance.py", line 465, in _execute_task
    result = _execute_callable(context=context, **execute_callable_kwargs)
             ^^^^^^^^^^^^^^^^^^^^^^^^^^^^^^^^^^^^^^^^^^^^^^^^^^^^^^^^^^^^^
  File "/home/airflow/.local/lib/python3.12/site-packages/airflow/models/taskinstance.py", line 432, in _execute_callable
    return execute_callable(context=context, **execute_callable_kwargs)
           ^^^^^^^^^^^^^^^^^^^^^^^^^^^^^^^^^^^^^^^^^^^^^^^^^^^^^^^^^^^^
  File "/home/airflow/.local/lib/python3.12/site-packages/airflow/models/baseoperator.py", line 400, in wrapper
    return func(self, *args, **kwargs)
           ^^^^^^^^^^^^^^^^^^^^^^^^^^^
  File "/home/airflow/.local/lib/python3.12/site-packages/airflow/operators/python.py", line 235, in execute
    return_value = self.execute_callable()
                   ^^^^^^^^^^^^^^^^^^^^^^^
  File "/home/airflow/.local/lib/python3.12/site-packages/airflow/operators/python.py", line 252, in execute_callable
    return self.python_callable(*self.op_args, **self.op_kwargs)
           ^^^^^^^^^^^^^^^^^^^^^^^^^^^^^^^^^^^^^^^^^^^^^^^^^^^^^
  File "/opt/airflow/dags/swapi_to_kafka_dag.py", line 21, in fetch_and_produce
    response = requests.get(swapi_url)
               ^^^^^^^^^^^^^^^^^^^^^^^
  File "/home/airflow/.local/lib/python3.12/site-packages/requests/api.py", line 73, in get
    return request("get", url, params=params, **kwargs)
           ^^^^^^^^^^^^^^^^^^^^^^^^^^^^^^^^^^^^^^^^^^^^
  File "/home/airflow/.local/lib/python3.12/site-packages/requests/api.py", line 59, in request
    return session.request(method=method, url=url, **kwargs)
           ^^^^^^^^^^^^^^^^^^^^^^^^^^^^^^^^^^^^^^^^^^^^^^^^^
  File "/home/airflow/.local/lib/python3.12/site-packages/requests/sessions.py", line 589, in request
    resp = self.send(prep, **send_kwargs)
           ^^^^^^^^^^^^^^^^^^^^^^^^^^^^^^
  File "/home/airflow/.local/lib/python3.12/site-packages/requests/sessions.py", line 703, in send
    r = adapter.send(request, **kwargs)
        ^^^^^^^^^^^^^^^^^^^^^^^^^^^^^^^
  File "/home/airflow/.local/lib/python3.12/site-packages/requests/adapters.py", line 517, in send
    raise SSLError(e, request=request)
requests.exceptions.SSLError: HTTPSConnectionPool(host='swapi.dev', port=443): Max retries exceeded with url: /api/people/1/ (Caused by SSLError(SSLCertVerificationError(1, '[SSL: CERTIFICATE_VERIFY_FAILED] certificate verify failed: certificate has expired (_ssl.c:1000)')))
[2025-06-05T23:12:00.852+0000] {taskinstance.py:1205} INFO - Marking task as FAILED. dag_id=swapi_to_kafka_dag, task_id=fetch_swapi_and_send_to_kafka, execution_date=20250605T231000, start_date=20250605T231200, end_date=20250605T231200
[2025-06-05T23:12:00.861+0000] {standard_task_runner.py:110} ERROR - Failed to execute job 4 for task fetch_swapi_and_send_to_kafka (HTTPSConnectionPool(host='swapi.dev', port=443): Max retries exceeded with url: /api/people/1/ (Caused by SSLError(SSLCertVerificationError(1, '[SSL: CERTIFICATE_VERIFY_FAILED] certificate verify failed: certificate has expired (_ssl.c:1000)'))); 191)
[2025-06-05T23:12:00.910+0000] {local_task_job_runner.py:240} INFO - Task exited with return code 1
[2025-06-05T23:12:00.923+0000] {taskinstance.py:3482} INFO - 0 downstream tasks scheduled from follow-on schedule check
[2025-06-05T23:12:00.924+0000] {local_task_job_runner.py:222} INFO - ::endgroup::
