[2025-06-06T09:03:24.994+0000] {local_task_job_runner.py:120} INFO - ::group::Pre task execution logs
[2025-06-06T09:03:25.013+0000] {taskinstance.py:2073} INFO - Dependencies all met for dep_context=non-requeueable deps ti=<TaskInstance: pokemon_partitioned_to_kafka.fetch_pokemon_and_send_partitioned_to_kafka scheduled__2025-06-06T09:02:00+00:00 [queued]>
[2025-06-06T09:03:25.018+0000] {taskinstance.py:2073} INFO - Dependencies all met for dep_context=requeueable deps ti=<TaskInstance: pokemon_partitioned_to_kafka.fetch_pokemon_and_send_partitioned_to_kafka scheduled__2025-06-06T09:02:00+00:00 [queued]>
[2025-06-06T09:03:25.019+0000] {taskinstance.py:2303} INFO - Starting attempt 1 of 1
[2025-06-06T09:03:25.028+0000] {taskinstance.py:2327} INFO - Executing <Task(PythonOperator): fetch_pokemon_and_send_partitioned_to_kafka> on 2025-06-06 09:02:00+00:00
[2025-06-06T09:03:25.034+0000] {logging_mixin.py:188} WARNING - /home/***/.local/lib/python3.12/site-packages/***/task/task_runner/standard_task_runner.py:61 DeprecationWarning: This process (pid=1842) is multi-threaded, use of fork() may lead to deadlocks in the child.
[2025-06-06T09:03:25.036+0000] {standard_task_runner.py:63} INFO - Started process 1843 to run task
[2025-06-06T09:03:25.034+0000] {standard_task_runner.py:90} INFO - Running: ['***', 'tasks', 'run', 'pokemon_partitioned_to_kafka', 'fetch_pokemon_and_send_partitioned_to_kafka', 'scheduled__2025-06-06T09:02:00+00:00', '--job-id', '90', '--raw', '--subdir', 'DAGS_FOLDER/pkapi_to_kafka_dag.py', '--cfg-path', '/tmp/tmpkwiiazzx']
[2025-06-06T09:03:25.036+0000] {standard_task_runner.py:91} INFO - Job 90: Subtask fetch_pokemon_and_send_partitioned_to_kafka
[2025-06-06T09:03:25.046+0000] {logging_mixin.py:188} WARNING - /home/***/.local/lib/python3.12/site-packages/***/settings.py:195 DeprecationWarning: The sql_alchemy_conn option in [core] has been moved to the sql_alchemy_conn option in [database] - the old setting has been used, but please update your config.
[2025-06-06T09:03:25.074+0000] {task_command.py:426} INFO - Running <TaskInstance: pokemon_partitioned_to_kafka.fetch_pokemon_and_send_partitioned_to_kafka scheduled__2025-06-06T09:02:00+00:00 [running]> on host 856ef77f0083
[2025-06-06T09:03:25.142+0000] {taskinstance.py:2644} INFO - Exporting env vars: AIRFLOW_CTX_DAG_OWNER='***' AIRFLOW_CTX_DAG_ID='pokemon_partitioned_to_kafka' AIRFLOW_CTX_TASK_ID='fetch_pokemon_and_send_partitioned_to_kafka' AIRFLOW_CTX_EXECUTION_DATE='2025-06-06T09:02:00+00:00' AIRFLOW_CTX_TRY_NUMBER='1' AIRFLOW_CTX_DAG_RUN_ID='scheduled__2025-06-06T09:02:00+00:00'
[2025-06-06T09:03:25.143+0000] {taskinstance.py:430} INFO - ::endgroup::
[2025-06-06T09:03:31.001+0000] {logging_mixin.py:188} INFO - Error fetching Pokémon ID 1: HTTPSConnectionPool(host='pokeapi.co', port=443): Read timed out. (read timeout=5)
[2025-06-06T09:03:39.007+0000] {logging_mixin.py:188} INFO - Error fetching Pokémon ID 2: HTTPSConnectionPool(host='pokeapi.co', port=443): Max retries exceeded with url: /api/v2/pokemon/2/ (Caused by NewConnectionError('<urllib3.connection.HTTPSConnection object at 0xffff855bfb30>: Failed to establish a new connection: [Errno -3] Temporary failure in name resolution'))
[2025-06-06T09:03:47.015+0000] {logging_mixin.py:188} INFO - Error fetching Pokémon ID 3: HTTPSConnectionPool(host='pokeapi.co', port=443): Max retries exceeded with url: /api/v2/pokemon/3/ (Caused by NewConnectionError('<urllib3.connection.HTTPSConnection object at 0xffff855bf800>: Failed to establish a new connection: [Errno -3] Temporary failure in name resolution'))
[2025-06-06T09:37:40.610+0000] {logging_mixin.py:188} INFO - Error fetching Pokémon ID 4: HTTPSConnectionPool(host='pokeapi.co', port=443): Max retries exceeded with url: /api/v2/pokemon/4/ (Caused by NewConnectionError('<urllib3.connection.HTTPSConnection object at 0xffff855bf8f0>: Failed to establish a new connection: [Errno -3] Temporary failure in name resolution'))
[2025-06-06T09:37:48.618+0000] {logging_mixin.py:188} INFO - Error fetching Pokémon ID 5: HTTPSConnectionPool(host='pokeapi.co', port=443): Max retries exceeded with url: /api/v2/pokemon/5/ (Caused by NewConnectionError('<urllib3.connection.HTTPSConnection object at 0xffff855bf9e0>: Failed to establish a new connection: [Errno -3] Temporary failure in name resolution'))
[2025-06-06T09:37:52.421+0000] {logging_mixin.py:188} INFO - Error fetching Pokémon ID 6: HTTPSConnectionPool(host='pokeapi.co', port=443): Max retries exceeded with url: /api/v2/pokemon/6/ (Caused by NewConnectionError('<urllib3.connection.HTTPSConnection object at 0xffff855ec710>: Failed to establish a new connection: [Errno -2] Name or service not known'))
[2025-06-06T09:37:52.450+0000] {logging_mixin.py:188} INFO - Error fetching Pokémon ID 7: HTTPSConnectionPool(host='pokeapi.co', port=443): Max retries exceeded with url: /api/v2/pokemon/7/ (Caused by NewConnectionError('<urllib3.connection.HTTPSConnection object at 0xffff855eca70>: Failed to establish a new connection: [Errno -2] Name or service not known'))
[2025-06-06T09:37:52.455+0000] {logging_mixin.py:188} INFO - Error fetching Pokémon ID 8: HTTPSConnectionPool(host='pokeapi.co', port=443): Max retries exceeded with url: /api/v2/pokemon/8/ (Caused by NewConnectionError('<urllib3.connection.HTTPSConnection object at 0xffff855eca70>: Failed to establish a new connection: [Errno -2] Name or service not known'))
[2025-06-06T09:37:52.459+0000] {logging_mixin.py:188} INFO - Error fetching Pokémon ID 9: HTTPSConnectionPool(host='pokeapi.co', port=443): Max retries exceeded with url: /api/v2/pokemon/9/ (Caused by NewConnectionError('<urllib3.connection.HTTPSConnection object at 0xffff855eca70>: Failed to establish a new connection: [Errno -2] Name or service not known'))
[2025-06-06T09:37:52.462+0000] {logging_mixin.py:188} INFO - Error fetching Pokémon ID 10: HTTPSConnectionPool(host='pokeapi.co', port=443): Max retries exceeded with url: /api/v2/pokemon/10/ (Caused by NewConnectionError('<urllib3.connection.HTTPSConnection object at 0xffff855ecfb0>: Failed to establish a new connection: [Errno -2] Name or service not known'))
[2025-06-06T09:37:52.476+0000] {logging_mixin.py:188} INFO - Error fetching Pokémon ID 11: HTTPSConnectionPool(host='pokeapi.co', port=443): Max retries exceeded with url: /api/v2/pokemon/11/ (Caused by NewConnectionError('<urllib3.connection.HTTPSConnection object at 0xffff855ed190>: Failed to establish a new connection: [Errno -2] Name or service not known'))
[2025-06-06T09:37:52.480+0000] {logging_mixin.py:188} INFO - Error fetching Pokémon ID 12: HTTPSConnectionPool(host='pokeapi.co', port=443): Max retries exceeded with url: /api/v2/pokemon/12/ (Caused by NewConnectionError('<urllib3.connection.HTTPSConnection object at 0xffff855ecfb0>: Failed to establish a new connection: [Errno -2] Name or service not known'))
[2025-06-06T09:37:52.485+0000] {logging_mixin.py:188} INFO - Error fetching Pokémon ID 13: HTTPSConnectionPool(host='pokeapi.co', port=443): Max retries exceeded with url: /api/v2/pokemon/13/ (Caused by NewConnectionError('<urllib3.connection.HTTPSConnection object at 0xffff855ecbf0>: Failed to establish a new connection: [Errno -2] Name or service not known'))
[2025-06-06T09:37:52.503+0000] {logging_mixin.py:188} INFO - Error fetching Pokémon ID 14: HTTPSConnectionPool(host='pokeapi.co', port=443): Max retries exceeded with url: /api/v2/pokemon/14/ (Caused by NewConnectionError('<urllib3.connection.HTTPSConnection object at 0xffff855ed190>: Failed to establish a new connection: [Errno -2] Name or service not known'))
[2025-06-06T09:37:52.506+0000] {logging_mixin.py:188} INFO - Error fetching Pokémon ID 15: HTTPSConnectionPool(host='pokeapi.co', port=443): Max retries exceeded with url: /api/v2/pokemon/15/ (Caused by NewConnectionError('<urllib3.connection.HTTPSConnection object at 0xffff855ecbf0>: Failed to establish a new connection: [Errno -2] Name or service not known'))
[2025-06-06T09:37:52.509+0000] {logging_mixin.py:188} INFO - Error fetching Pokémon ID 16: HTTPSConnectionPool(host='pokeapi.co', port=443): Max retries exceeded with url: /api/v2/pokemon/16/ (Caused by NewConnectionError('<urllib3.connection.HTTPSConnection object at 0xffff855ed190>: Failed to establish a new connection: [Errno -2] Name or service not known'))
[2025-06-06T09:37:52.512+0000] {logging_mixin.py:188} INFO - Error fetching Pokémon ID 17: HTTPSConnectionPool(host='pokeapi.co', port=443): Max retries exceeded with url: /api/v2/pokemon/17/ (Caused by NewConnectionError('<urllib3.connection.HTTPSConnection object at 0xffff855ec440>: Failed to establish a new connection: [Errno -2] Name or service not known'))
[2025-06-06T09:37:52.515+0000] {logging_mixin.py:188} INFO - Error fetching Pokémon ID 18: HTTPSConnectionPool(host='pokeapi.co', port=443): Max retries exceeded with url: /api/v2/pokemon/18/ (Caused by NewConnectionError('<urllib3.connection.HTTPSConnection object at 0xffff855ed4c0>: Failed to establish a new connection: [Errno -2] Name or service not known'))
[2025-06-06T09:37:52.518+0000] {logging_mixin.py:188} INFO - Error fetching Pokémon ID 19: HTTPSConnectionPool(host='pokeapi.co', port=443): Max retries exceeded with url: /api/v2/pokemon/19/ (Caused by NewConnectionError('<urllib3.connection.HTTPSConnection object at 0xffff855ec440>: Failed to establish a new connection: [Errno -2] Name or service not known'))
[2025-06-06T09:37:52.519+0000] {python.py:237} INFO - Done. Returned value was: None
[2025-06-06T09:37:52.519+0000] {taskinstance.py:441} INFO - ::group::Post task execution logs
[2025-06-06T09:37:52.527+0000] {taskinstance.py:1205} INFO - Marking task as SUCCESS. dag_id=pokemon_partitioned_to_kafka, task_id=fetch_pokemon_and_send_partitioned_to_kafka, execution_date=20250606T090200, start_date=20250606T090325, end_date=20250606T093752
[2025-06-06T09:37:52.555+0000] {local_task_job_runner.py:240} INFO - Task exited with return code 0
[2025-06-06T09:37:52.569+0000] {taskinstance.py:3482} INFO - 0 downstream tasks scheduled from follow-on schedule check
[2025-06-06T09:37:52.570+0000] {local_task_job_runner.py:222} INFO - ::endgroup::
